Workbook

Sheet Dropdownlist
A1: Status | B1: Country | C1: Countries (if multiple) or Region | D1: Disease/condition | E1: Pending question | F1: Need RRA | G1: RRA Risk level | H1: Need EIS | I1: Type | J1: EIS_first_draft_by | K1: Need DON | L1: GPW 13 Desc_start | M1: GPW 13 Desc_detect | N1: GPW 13 Desc_notify | O1: GPW 13 Desc_response
A2: Closed | B2: Afghanistan | C2: AFR | D2: Acute febrile jaundice syndrome | E2: No | F2: No | G2: High | H2: No | I2: Update existing EIS | J2: WHO RO | K2: No | L2: First visit to health care facility | M2: First sample collection date | O2: Incident management system set up
A3: Unknown | B3: Åland Islands | C3: AMR | D3: Acute Hemorrhagic Fever | E3: Yes | F3: Decision pending | G3: Moderate | H3: Decision pending | I3: EIS anouncement | J3: Not applicable | K3: Decision pending | L3: Date of suspected primary case | M3: Ministry of health press release date | O3: Vaccination campaign started
A4: Open | B4: Multiple | C4: Not applicable | D4: Acute kidney injury | F4: Yes | G4: Very High | H4: Yes | I4: New EIS | J4: WHO HQ | K4: Yes | L4: Symptom-onset date of first reported case (=initial case) | M4: First confirmatory laboratory test | N4: Date national governmental agency, the International Health Regulation national focal point reported to WHO | O4: Field investigation started
B5: Albania | C5: EMR | D5: AMR Klebsiella pneumoniae | G5: Low | I5: Not applicable | L5: Most likely exposure date (estimated) | M5: Rapid diagnostic test date | O5: Active surveillance initiated
B6: Algeria | C6: EUR | D6: Anthrax | G6: Not applicable | L6: First exposure date (estimated) | M6: First time diagnosed as suspected case | O6: Rapid response team deployed
B7: American Samoa | C7: SEAR | D7: Arboviruses | L7: Latest exposure date (estimated) | M7: Date other external party reported to ministry of health | O7: Active surveillance initiated
B8: Andorra | C8: WPR | D8: Avian influenza A (H10N3) | L8: Outbreak start date | M8: Date outbreak declared | O8: Risk communication started
B9: Angola | C9: Somalia, Ethiopia | D9: Avian influenza A (H10N5) + H3N2 | L9: Date of death of first reported case (=initial case) | M9: Date local health authority reported to ministry of health | O9: Date quarantine started
B10: Anguilla | C10: Mozambique, Malawi | D10: Avian influenza A (H1N1) v | L10: First report of the outbreak | M10: Date of preliminary laboratory test | O10: Vector control campaign launched
B11: Antigua and Barbuda | C11: EUR, AMR | D11: Avian influenza A (H1N2) | M11: Communication from laboratory to ministry of health | O11: Food/product recall started
B12: France | C12: Multi area | D12: Avian influenza A (H1N2)v
B13: Argentina | C13: Global | D13: Avian Influenza A (H3N8) | M13: Date first communication between third party Member States happened | O13: National emergency operation centre activated
B14: Armenia | C14: Niger, Nigeria | D14: Avian influenza A (H5N1) | M14: Date local health authority detected signal through media | O14: Expert group established
B15: Aruba | C15: Mexico, United States of America | D15: Avian influenza A (H5N6)
B16: Australia | C16: Australia, New Zealand, UAE | D16: Avian Influenza A (H9)
B17: Austria | C17: Chile, Armenia, Georgia | D17: Avian influenza A (H9N2)
B18: Azerbaijan | D18: Avian Influenza A(H3)v
B19: Bahamas | D19: Avian influenza A(H5)
B20: Bahrain | D20: Avian Influenza A(H9)
B21: Bangladesh | D21: Botulism
B22: Barbados | D22: Chandipura virus
B23: Belarus | D23: Chapare virus
B24: Belgium | D24: Chemical exposure
B25: Belize | D25: Chikungunya
B26: Benin | D26: Cholera
B27: Bermuda | D27: COVID - 19
B28: Bhutan | D28: COVID-19 (Omicron)
B29: Bolivia (Plurinational State of) | D29: Crimean-Congo hemorrhagic fever (CCHF)
... B90: Georgia | D90: Zika
B91: Germany
B92: Ghana
B93: Gibraltar
B94: Greece
B95: Greenland
B96: Grenada
B97: Guadeloupe
B98: Guam
B99: Guatemala
B100: Guernsey
...

Sheet product tracker
A1: Date of entry | B1: Status | C1: Product | D1: FP name | E1: disease_condition | F1: country | G1: Countries (if multiple) or Region | H1: daily signal tracker | I1: Daily signal tracker update entry | J1: EMS entry | K1: EMS event ID | L1: EMS comments | M1: Pending_question | N1: Pending question status | O1: PQ_closure_date | P1: Need_RRA | Q1: Version | R1: RRA status | S1: RRA_Decision_date | T1: RRA_start_date | U1: RRA_pub_date | V1: RRA National risk level | W1: RRA Regional risk level | X1: RRA Global risk level | Y1: Need_EIS | Z1: Type | AA1: EIS_first_draft_by | AB1: EIS status | AC1: EIS_decision_date | AD1: EIS_start_HQ_receive_date | AE1: EIS sent to Regional office | AF1: EIS sent to NFP | AG1: Feedback NFP | AH1: EIS_pub_date | AI1: Need_DON | AJ1: DON_start_date | AK1: DON_pub_date | AL1: Comments | AM1: countrycode | AN1: RRA_indic | AO1: EIS_indic | AP1: DON_indic | AQ1: PQ_indic | AR1: daily_list
A2: 36526 | B2: Closed | C2: {=IF(SUM(Table2[[#This Row],[PQ_indic]],Table2[[#This Row],[RRA_indic]],Table2[[#This Row],[EIS_indic]],Table2[[#This Row],[DON_indic]])=8, "Missing data", (IF(AND(Table2[[#This Row],[Pending_question]]="Yes", OR( Table2[[#This Row],[Need_RRA]]="No", ISBLANK(Table2[[#This Row],[Need_RRA]])), OR(Table2[[#This Row],[Need_EIS]]="No", ISBLANK(Table2[[#This Row],[Need_EIS]])), OR(Table2[[#This Row],[Need_DON]]="No", ISBLANK(Table2[[#This Row],[Need_DON]]) )),"Question, no products",( IF( AND(Table2[[#This Row],[Pending_question]]="Yes", ISBLANK(Table2[[#This Row],[PQ_closure_date]])), (IF(SUM(Table2[[#This Row],[RRA_indic]],Table2[[#This Row],[EIS_indic]],Table2[[#This Row],[DON_indic]])=0, "Open Question, all products done",(I447IF(OR(Table2[[#This Row],[RRA_indic]]=2, Table2[[#This Row],[EIS_indic]]=2, Table2[[#This Row],[DON_indic]]=2),"Question, Products unknown",IF(AND(Table2[[#This Row],[RRA_indic]]=1, Table2[[#This Row],[EIS_indic]]=1, Table2[[#This Row],[DON_indic]]=1), "Open Question, RRA, EIS, DON", IF(AND(Table2[[#This Row],[RRA_indic]]=1, Table2[[#This Row],[EIS_indic]]=1), "Open Question, RRA, EIS",IF(AND(Table2[[#This Row],[RRA_indic]]=1, Table2[[#This Row],[DON_indic]]=1), "Open Question, RRA, DON", IF(AND(Table2[[#This Row],[EIS_indic]]=1, Table2[[#This Row],[DON_indic]]=1), "Open Question, EIS, DON",IF(Table2[[#This Row],[RRA_indic]]=1, "Open Question, RRA", IF(Table2[[#This Row],[EIS_indic]]=1, "Open Question, EIS", "Open Question, DON")))))))))), (IF(SUM(Table2[[#This Row],[RRA_indic]],Table2[[#This Row],[EIS_indic]],Table2[[#This Row],[DON_indic]])=0, "All Products done",(IF(OR(Table2[[#This Row],[RRA_indic]]=2, Table2[[#This Row],[EIS_indic]]=2, Table2[[#This Row],[DON_indic]]=2),"Unknown", IF(AND(Table2[[#This Row],[RRA_indic]]=1, Table2[[#This Row],[EIS_indic]]=1, Table2[[#This Row],[DON_indic]]=1), "Open RRA, EIS, DON", IF(AND(Table2[[#This Row],[RRA_indic]]=1, Table2[[#This Row],[EIS_indic]]=1), "Open RRA, EIS", IF(AND(Table2[[#This Row],[RRA_indic]]=1, Table2[[#This Row],[DON_indic]]=1), "Open RRA, DON", IF(AND(Table2[[#This Row],[EIS_indic]]=1, Table2[[#This Row],[DON_indic]]=1), "Open EIS, DON", IF(Table2[[#This Row],[RRA_indic]]=1, "Open RRA", IF(Table2[[#This Row],[EIS_indic]]=1, "Open EIS", "Open DON")))))))))))))))} -> All Products done | D2: Lidia | E2: Acute Hemorrhagic Fever | F2: Angola | G2: Not applicable | M2: No | P2: No | Q2: Not applicable | Y2: no | AI2: no | AL2: 21 June: signal, additional information requested from AFRO / 24 June: Malaria confirmed | AM2: =VLOOKUP(Table2[[#This Row],[country]],Countrycode!A:B,2,FALSE) -> AGO | AN2: =IF(ISBLANK(Table2[[#This Row],[Need_RRA]]), 2,(IF(Table2[[#This Row],[Need_RRA]]="No", 0, (IF(AND(Table2[[#This Row],[Need_RRA]]="Yes", Table2[[#This Row],[RRA_pub_date]]=""),1, 0))))) -> 0 | AO2: =IF(ISBLANK(Table2[[#This Row],[Need_EIS]]), 2,(IF(Table2[[#This Row],[Need_EIS]]="No", 0, (IF(AND(Table2[[#This Row],[Need_EIS]]="Yes", Table2[[#This Row],[EIS_pub_date]]=""),1, 0))))) -> 0 | AP2: =IF(ISBLANK(Table2[[#This Row],[Need_DON]]), 2,(IF(Table2[[#This Row],[Need_DON]]="No", 0, (IF(AND(Table2[[#This Row],[Need_DON]]="Yes", Table2[[#This Row],[DON_pub_date]]=""),1, 0))))) -> 0 | AQ2: =IF(ISBLANK(Table2[[#This Row],[Pending_question]]), 2,(IF(Table2[[#This Row],[Pending_question]]="Yes", 1, 0))) -> 0
A3: 36526 | B3: Closed | C3: {=IF(SUM(Table2[[#This Row],[PQ_indic]],Table2[[#This Row],[RRA_indic]],Table2[[#This Row],[EIS_indic]],Table2[[#This Row],[DON_indic]])=8, "Missing data", (IF(AND(Table2[[#This Row],[Pending_question]]="Yes", OR( Table2[[#This Row],[Need_RRA]]="No", ISBLANK(Table2[[#This Row],[Need_RRA]])), OR(Table2[[#This Row],[Need_EIS]]="No", ISBLANK(Table2[[#This Row],[Need_EIS]])), OR(Table2[[#This Row],[Need_DON]]="No", ISBLANK(Table2[[#This Row],[Need_DON]]) )),"Question, no products",( IF( AND(Table2[[#This Row],[Pending_question]]="Yes", ISBLANK(Table2[[#This Row],[PQ_closure_date]])), (IF(SUM(Table2[[#This Row],[RRA_indic]],Table2[[#This Row],[EIS_indic]],Table2[[#This Row],[DON_indic]])=0, "Open Question, all products done",(I447IF(OR(Table2[[#This Row],[RRA_indic]]=2, Table2[[#This Row],[EIS_indic]]=2, Table2[[#This Row],[DON_indic]]=2),"Question, Products unknown",IF(AND(Table2[[#This Row],[RRA_indic]]=1, Table2[[#This Row],[EIS_indic]]=1, Table2[[#This Row],[DON_indic]]=1), "Open Question, RRA, EIS, DON", IF(AND(Table2[[#This Row],[RRA_indic]]=1, Table2[[#This Row],[EIS_indic]]=1), "Open Question, RRA, EIS",IF(AND(Table2[[#This Row],[RRA_indic]]=1, Table2[[#This Row],[DON_indic]]=1), "Open Question, RRA, DON", IF(AND(Table2[[#This Row],[EIS_indic]]=1, Table2[[#This Row],[DON_indic]]=1), "Open Question, EIS, DON",IF(Table2[[#This Row],[RRA_indic]]=1, "Open Question, RRA", IF(Table2[[#This Row],[EIS_indic]]=1, "Open Question, EIS", "Open Question, DON")))))))))), (IF(SUM(Table2[[#This Row],[RRA_indic]],Table2[[#This Row],[EIS_indic]],Table2[[#This Row],[DON_indic]])=0, "All Products done",(IF(OR(Table2[[#This Row],[RRA_indic]]=2, Table2[[#This Row],[EIS_indic]]=2, Table2[[#This Row],[DON_indic]]=2),"Unknown", IF(AND(Table2[[#This Row],[RRA_indic]]=1, Table2[[#This Row],[EIS_indic]]=1, Table2[[#This Row],[DON_indic]]=1), "Open RRA, EIS, DON", IF(AND(Table2[[#This Row],[RRA_indic]]=1, Table2[[#This Row],[EIS_indic]]=1), "Open RRA, EIS", IF(AND(Table2[[#This Row],[RRA_indic]]=1, Table2[[#This Row],[DON_indic]]=1), "Open RRA, DON", IF(AND(Table2[[#This Row],[EIS_indic]]=1, Table2[[#This Row],[DON_indic]]=1), "Open EIS, DON", IF(Table2[[#This Row],[RRA_indic]]=1, "Open RRA", IF(Table2[[#This Row],[EIS_indic]]=1, "Open EIS", "Open DON")))))))))))))))} -> All Products done | D3: Anastasia | E3: Cholera | F3: Democratic Republic of the Congo | G3: Not applicable | M3: No | P3: No | Q3: Not applicable | R3: 23 June: Awaiting las comments from WCO. 24 June: On 24 June, AFRO suggested to change the risk levels in the risk assessment table. 25 June: during a 3L TC it was decided to drop this RRA as the situation has changed significantly and RRA is not required at the moment. 2 July: Not required at the moment | Y3: no | AB3: 25 June: No plans | AI3: no | AM3: =VLOOKUP(Table2[[#This Row],[country]],Countrycode!A:B,2,FALSE) -> COD | AN3: =IF(ISBLANK(Table2[[#This Row],[Need_RRA]]), 2,(IF(Table2[[#This Row],[Need_RRA]]="No", 0, (IF(AND(Table2[[#This Row],[Need_RRA]]="Yes", Table2[[#This Row],[RRA_pub_date]]=""),1, 0))))) -> 0 | AO3: =IF(ISBLANK(Table2[[#This Row],[Need_EIS]]), 2,(IF(Table2[[#This Row],[Need_EIS]]="No", 0, (IF(AND(Table2[[#This Row],[Need_EIS]]="Yes", Table2[[#This Row],[EIS_pub_date]]=""),1, 0))))) -> 0 | AP3: =IF(ISBLANK(Table2[[#This Row],[Need_DON]]), 2,(IF(Table2[[#This Row],[Need_DON]]="No", 0, (IF(AND(Table2[[#This Row],[Need_DON]]="Yes", Table2[[#This Row],[DON_pub_date]]=""),1, 0))))) -> 0 | AQ3: =IF(ISBLANK(Table2[[#This Row],[Pending_question]]), 2,(IF(Table2[[#This Row],[Pending_question]]="Yes", 1, 0))) -> 0
A4: 36526 | B4: Closed | C4: {=IF(SUM(Table2[[#This Row],[PQ_indic]],Table2[[#This Row],[RRA_indic]],Table2[[#This Row],[EIS_indic]],Table2[[#This Row],[DON_indic]])=8, "Missing data", (IF(AND(Table2[[#This Row],[Pending_question]]="Yes", OR( Table2[[#This Row],[Need_RRA]]="No", ISBLANK(Table2[[#This Row],[Need_RRA]])), OR(Table2[[#This Row],[Need_EIS]]="No", ISBLANK(Table2[[#This Row],[Need_EIS]])), OR(Table2[[#This Row],[Need_DON]]="No", ISBLANK(Table2[[#This Row],[Need_DON]]) )),"Question, no products",( IF( AND(Table2[[#This Row],[Pending_question]]="Yes", ISBLANK(Table2[[#This Row],[PQ_closure_date]])), (IF(SUM(Table2[[#This Row],[RRA_indic]],Table2[[#This Row],[EIS_indic]],Table2[[#This Row],[DON_indic]])=0, "Open Question, all products done",(I447IF(OR(Table2[[#This Row],[RRA_indic]]=2, Table2[[#This Row],[EIS_indic]]=2, Table2[[#This Row],[DON_indic]]=2),"Question, Products unknown",IF(AND(Table2[[#This Row],[RRA_indic]]=1, Table2[[#This Row],[EIS_indic]]=1, Table2[[#This Row],[DON_indic]]=1), "Open Question, RRA, EIS, DON", IF(AND(Table2[[#This Row],[RRA_indic]]=1, Table2[[#This Row],[EIS_indic]]=1), "Open Question, RRA, EIS",IF(AND(Table2[[#This Row],[RRA_indic]]=1, Table2[[#This Row],[DON_indic]]=1), "Open Question, RRA, DON", IF(AND(Table2[[#This Row],[EIS_indic]]=1, Table2[[#This Row],[DON_indic]]=1), "Open Question, EIS, DON",IF(Table2[[#This Row],[RRA_indic]]=1, "Open Question, RRA", IF(Table2[[#This Row],[EIS_indic]]=1, "Open Question, EIS", "Open Question, DON")))))))))), (IF(SUM(Table2[[#This Row],[RRA_indic]],Table2[[#This Row],[EIS_indic]],Table2[[#This Row],[DON_indic]])=0, "All Products done",(IF(OR(Table2[[#This Row],[RRA_indic]]=2, Table2[[#This Row],[EIS_indic]]=2, Table2[[#This Row],[DON_indic]]=2),"Unknown", IF(AND(Table2[[#This Row],[RRA_indic]]=1, Table2[[#This Row],[EIS_indic]]=1, Table2[[#This Row],[DON_indic]]=1), "Open RRA, EIS, DON", IF(AND(Table2[[#This Row],[RRA_indic]]=1, Table2[[#This Row],[EIS_indic]]=1), "Open RRA, EIS", IF(AND(Table2[[#This Row],[RRA_indic]]=1, Table2[[#This Row],[DON_indic]]=1), "Open RRA, DON", IF(AND(Table2[[#This Row],[EIS_indic]]=1, Table2[[#This Row],[DON_indic]]=1), "Open EIS, DON", IF(Table2[[#This Row],[RRA_indic]]=1, "Open RRA", IF(Table2[[#This Row],[EIS_indic]]=1, "Open EIS", "Open DON")))))))))))))))} -> All Products done | D4: Anastasia | E4: Malaria | F4: Ethiopia | G4: Not applicable | M4: No | P4: No | Q4: Not applicable | R4: pending | Y4: no | AB4: PHSA done by FES in April | AI4: no | AM4: =VLOOKUP(Table2[[#This Row],[country]],Countrycode!A:B,2,FALSE) -> ETH | AN4: =IF(ISBLANK(Table2[[#This Row],[Need_RRA]]), 2,(IF(Table2[[#This Row],[Need_RRA]]="No", 0, (IF(AND(Table2[[#This Row],[Need_RRA]]="Yes", Table2[[#This Row],[RRA_pub_date]]=""),1, 0))))) -> 0 | AO4: =IF(ISBLANK(Table2[[#This Row],[Need_EIS]]), 2,(IF(Table2[[#This Row],[Need_EIS]]="No", 0, (IF(AND(Table2[[#This Row],[Need_EIS]]="Yes", Table2[[#This Row],[EIS_pub_date]]=""),1, 0))))) -> 0 | AP4: =IF(ISBLANK(Table2[[#This Row],[Need_DON]]), 2,(IF(Table2[[#This Row],[Need_DON]]="No", 0, (IF(AND(Table2[[#This Row],[Need_DON]]="Yes", Table2[[#This Row],[DON_pub_date]]=""),1, 0))))) -> 0 | AQ4: =IF(ISBLANK(Table2[[#This Row],[Pending_question]]), 2,(IF(Table2[[#This Row],[Pending_question]]="Yes", 1, 0))) -> 0
A5: 36526 | B5: Closed | C5: {=IF(SUM(Table2[[#This Row],[PQ_indic]],Table2[[#This Row],[RRA_indic]],Table2[[#This Row],[EIS_indic]],Table2[[#This Row],[DON_indic]])=8, "Missing data", (IF(AND(Table2[[#This Row],[Pending_question]]="Yes", OR( Table2[[#This Row],[Need_RRA]]="No", ISBLANK(Table2[[#This Row],[Need_RRA]])), OR(Table2[[#This Row],[Need_EIS]]="No", ISBLANK(Table2[[#This Row],[Need_EIS]])), OR(Table2[[#This Row],[Need_DON]]="No", ISBLANK(Table2[[#This Row],[Need_DON]]) )),"Question, no products",( IF( AND(Table2[[#This Row],[Pending_question]]="Yes", ISBLANK(Table2[[#This Row],[PQ_closure_date]])), (IF(SUM(Table2[[#This Row],[RRA_indic]],Table2[[#This Row],[EIS_indic]],Table2[[#This Row],[DON_indic]])=0, "Open Question, all products done",(I447IF(OR(Table2[[#This Row],[RRA_indic]]=2, Table2[[#This Row],[EIS_indic]]=2, Table2[[#This Row],[DON_indic]]=2),"Question, Products unknown",IF(AND(Table2[[#This Row],[RRA_indic]]=1, Table2[[#This Row],[EIS_indic]]=1, Table2[[#This Row],[DON_indic]]=1), "Open Question, RRA, EIS, DON", IF(AND(Table2[[#This Row],[RRA_indic]]=1, Table2[[#This Row],[EIS_indic]]=1), "Open Question, RRA, EIS",IF(AND(Table2[[#This Row],[RRA_indic]]=1, Table2[[#This Row],[DON_indic]]=1), "Open Question, RRA, DON", IF(AND(Table2[[#This Row],[EIS_indic]]=1, Table2[[#This Row],[DON_indic]]=1), "Open Question, EIS, DON",IF(Table2[[#This Row],[RRA_indic]]=1, "Open Question, RRA", IF(Table2[[#This Row],[EIS_indic]]=1, "Open Question, EIS", "Open Question, DON")))))))))), (IF(SUM(Table2[[#This Row],[RRA_indic]],Table2[[#This Row],[EIS_indic]],Table2[[#This Row],[DON_indic]])=0, "All Products done",(IF(OR(Table2[[#This Row],[RRA_indic]]=2, Table2[[#This Row],[EIS_indic]]=2, Table2[[#This Row],[DON_indic]]=2),"Unknown", IF(AND(Table2[[#This Row],[RRA_indic]]=1, Table2[[#This Row],[EIS_indic]]=1, Table2[[#This Row],[DON_indic]]=1), "Open RRA, EIS, DON", IF(AND(Table2[[#This Row],[RRA_indic]]=1, Table2[[#This Row],[EIS_indic]]=1), "Open RRA, EIS", IF(AND(Table2[[#This Row],[RRA_indic]]=1, Table2[[#This Row],[DON_indic]]=1), "Open RRA, DON", IF(AND(Table2[[#This Row],[EIS_indic]]=1, Table2[[#This Row],[DON_indic]]=1), "Open EIS, DON", IF(Table2[[#This Row],[RRA_indic]]=1, "Open RRA", IF(Table2[[#This Row],[EIS_indic]]=1, "Open EIS", "Open DON")))))))))))))))} -> All Products done | D5: Dunja | E5: Malaria | F5: Niger | G5: Not applicable | M5: No | P5: No | Q5: Not applicable | R5: 5 October: need RRA? | Y5: no | AI5: no | AL5: Still waiting decision from AFRO ( waiting for Malaria TT advise) | AM5: =VLOOKUP(Table2[[#This Row],[country]],Countrycode!A:B,2,FALSE) -> NER | AN5: =IF(ISBLANK(Table2[[#This Row],[Need_RRA]]), 2,(IF(Table2[[#This Row],[Need_RRA]]="No", 0, (IF(AND(Table2[[#This Row],[Need_RRA]]="Yes", Table2[[#This Row],[RRA_pub_date]]=""),1, 0))))) -> 0 | AO5: =IF(ISBLANK(Table2[[#This Row],[Need_EIS]]), 2,(IF(Table2[[#This Row],[Need_EIS]]="No", 0, (IF(AND(Table2[[#This Row],[Need_EIS]]="Yes", Table2[[#This Row],[EIS_pub_date]]=""),1, 0))))) -> 0 | AP5: =IF(ISBLANK(Table2[[#This Row],[Need_DON]]), 2,(IF(Table2[[#This Row],[Need_DON]]="No", 0, (IF(AND(Table2[[#This Row],[Need_DON]]="Yes", Table2[[#This Row],[DON_pub_date]]=""),1, 0))))) -> 0 | AQ5: =IF(ISBLANK(Table2[[#This Row],[Pending_question]]), 2,(IF(Table2[[#This Row],[Pending_question]]="Yes", 1, 0))) -> 0
A6: 36526 | B6: Closed | C6: {=IF(SUM(Table2[[#This Row],[PQ_indic]],Table2[[#This Row],[RRA_indic]],Table2[[#This Row],[EIS_indic]],Table2[[#This Row],[DON_indic]])=8, "Missing data", (IF(AND(Table2[[#This Row],[Pending_question]]="Yes", OR( Table2[[#This Row],[Need_RRA]]="No", ISBLANK(Table2[[#This Row],[Need_RRA]])), OR(Table2[[#This Row],[Need_EIS]]="No", ISBLANK(Table2[[#This Row],[Need_EIS]])), OR(Table2[[#This Row],[Need_DON]]="No", ISBLANK(Table2[[#This Row],[Need_DON]]) )),"Question, no products",( IF( AND(Table2[[#This Row],[Pending_question]]="Yes", ISBLANK(Table2[[#This Row],[PQ_closure_date]])), (IF(SUM(Table2[[#This Row],[RRA_indic]],Table2[[#This Row],[EIS_indic]],Table2[[#This Row],[DON_indic]])=0, "Open Question, all products done",(I447IF(OR(Table2[[#This Row],[RRA_indic]]=2, Table2[[#This Row],[EIS_indic]]=2, Table2[[#This Row],[DON_indic]]=2),"Question, Products unknown",IF(AND(Table2[[#This Row],[RRA_indic]]=1, Table2[[#This Row],[EIS_indic]]=1, Table2[[#This Row],[DON_indic]]=1), "Open Question, RRA, EIS, DON", IF(AND(Table2[[#This Row],[RRA_indic]]=1, Table2[[#This Row],[EIS_indic]]=1), "Open Question, RRA, EIS",IF(AND(Table2[[#This Row],[RRA_indic]]=1, Table2[[#This Row],[DON_indic]]=1), "Open Question, RRA, DON", IF(AND(Table2[[#This Row],[EIS_indic]]=1, Table2[[#This Row],[DON_indic]]=1), "Open Question, EIS, DON",IF(Table2[[#This Row],[RRA_indic]]=1, "Open Question, RRA", IF(Table2[[#This Row],[EIS_indic]]=1, "Open Question, EIS", "Open Question, DON")))))))))), (IF(SUM(Table2[[#This Row],[RRA_indic]],Table2[[#This Row],[EIS_indic]],Table2[[#This Row],[DON_indic]])=0, "All Products done",(IF(OR(Table2[[#This Row],[RRA_indic]]=2, Table2[[#This Row],[EIS_indic]]=2, Table2[[#This Row],[DON_indic]]=2),"Unknown", IF(AND(Table2[[#This Row],[RRA_indic]]=1, Table2[[#This Row],[EIS_indic]]=1, Table2[[#This Row],[DON_indic]]=1), "Open RRA, EIS, DON", IF(AND(Table2[[#This Row],[RRA_indic]]=1, Table2[[#This Row],[EIS_indic]]=1), "Open RRA, EIS", IF(AND(Table2[[#This Row],[RRA_indic]]=1, Table2[[#This Row],[DON_indic]]=1), "Open RRA, DON", IF(AND(Table2[[#This Row],[EIS_indic]]=1, Table2[[#This Row],[DON_indic]]=1), "Open EIS, DON", IF(Table2[[#This Row],[RRA_indic]]=1, "Open RRA", IF(Table2[[#This Row],[EIS_indic]]=1, "Open EIS", "Open DON")))))))))))))))} -> All Products done | D6: Dunja | E6: Undiagnosed disease - suspected Viral Hemorrhagic Fever | F6: Sao Tome and Principe | G6: Not applicable | I6: Not applicable | M6: No | P6: No | Q6: Not applicable | S6: Not applicable | U6: Not applicable | V6: Not applicable | W6: Not applicable | X6: Not applicable | Y6: No | Z6: Not applicable | AC6: Not applicable | AD6: Not applicable | AE6: Not applicable | AF6: Not applicable | AG6: Not applicable | AH6: Not applicable | AI6: No | AM6: =VLOOKUP(Table2[[#This Row],[country]],Countrycode!A:B,2,FALSE) -> STP | AN6: =IF(ISBLANK(Table2[[#This Row],[Need_RRA]]), 2,(IF(Table2[[#This Row],[Need_RRA]]="No", 0, (IF(AND(Table2[[#This Row],[Need_RRA]]="Yes", Table2[[#This Row],[RRA_pub_date]]=""),1, 0))))) -> 0 | AO6: =IF(ISBLANK(Table2[[#This Row],[Need_EIS]]), 2,(IF(Table2[[#This Row],[Need_EIS]]="No", 0, (IF(AND(Table2[[#This Row],[Need_EIS]]="Yes", Table2[[#This Row],[EIS_pub_date]]=""),1, 0))))) -> 0 | AP6: =IF(ISBLANK(Table2[[#This Row],[Need_DON]]), 2,(IF(Table2[[#This Row],[Need_DON]]="No", 0, (IF(AND(Table2[[#This Row],[Need_DON]]="Yes", Table2[[#This Row],[DON_pub_date]]=""),1, 0))))) -> 0 | AQ6: =IF(ISBLANK(Table2[[#This Row],[Pending_question]]), 2,(IF(Table2[[#This Row],[Pending_question]]="Yes", 1, 0))) -> 0
A7: 44322 | B7: Closed | C7: {=IF(SUM(Table2[[#This Row],[PQ_indic]],Table2[[#This Row],[RRA_indic]],Table2[[#This Row],[EIS_indic]],Table2[[#This Row],[DON_indic]])=8, "Missing data", (IF(AND(Table2[[#This Row],[Pending_question]]="Yes", OR( Table2[[#This Row],[Need_RRA]]="No", ISBLANK(Table2[[#This Row],[Need_RRA]])), OR(Table2[[#This Row],[Need_EIS]]="No", ISBLANK(Table2[[#This Row],[Need_EIS]])), OR(Table2[[#This Row],[Need_DON]]="No", ISBLANK(Table2[[#This Row],[Need_DON]]) )),"Question, no products",( IF( AND(Table2[[#This Row],[Pending_question]]="Yes", ISBLANK(Table2[[#This Row],[PQ_closure_date]])), (IF(SUM(Table2[[#This Row],[RRA_indic]],Table2[[#This Row],[EIS_indic]],Table2[[#This Row],[DON_indic]])=0, "Open Question, all products done",(I447IF(OR(Table2[[#This Row],[RRA_indic]]=2, Table2[[#This Row],[EIS_indic]]=2, Table2[[#This Row],[DON_indic]]=2),"Question, Products unknown",IF(AND(Table2[[#This Row],[RRA_indic]]=1, Table2[[#This Row],[EIS_indic]]=1, Table2[[#This Row],[DON_indic]]=1), "Open Question, RRA, EIS, DON", IF(AND(Table2[[#This Row],[RRA_indic]]=1, Table2[[#This Row],[EIS_indic]]=1), "Open Question, RRA, EIS",IF(AND(Table2[[#This Row],[RRA_indic]]=1, Table2[[#This Row],[DON_indic]]=1), "Open Question, RRA, DON", IF(AND(Table2[[#This Row],[EIS_indic]]=1, Table2[[#This Row],[DON_indic]]=1), "Open Question, EIS, DON",IF(Table2[[#This Row],[RRA_indic]]=1, "Open Question, RRA", IF(Table2[[#This Row],[EIS_indic]]=1, "Open Question, EIS", "Open Question, DON")))))))))), (IF(SUM(Table2[[#This Row],[RRA_indic]],Table2[[#This Row],[EIS_indic]],Table2[[#This Row],[DON_indic]])=0, "All Products done",(IF(OR(Table2[[#This Row],[RRA_indic]]=2, Table2[[#This Row],[EIS_indic]]=2, Table2[[#This Row],[DON_indic]]=2),"Unknown", IF(AND(Table2[[#This Row],[RRA_indic]]=1, Table2[[#This Row],[EIS_indic]]=1, Table2[[#This Row],[DON_indic]]=1), "Open RRA, EIS, DON", IF(AND(Table2[[#This Row],[RRA_indic]]=1, Table2[[#This Row],[EIS_indic]]=1), "Open RRA, EIS", IF(AND(Table2[[#This Row],[RRA_indic]]=1, Table2[[#This Row],[DON_indic]]=1), "Open RRA, DON", IF(AND(Table2[[#This Row],[EIS_indic]]=1, Table2[[#This Row],[DON_indic]]=1), "Open EIS, DON", IF(Table2[[#This Row],[RRA_indic]]=1, "Open RRA", IF(Table2[[#This Row],[EIS_indic]]=1, "Open EIS", "Open DON")))))))))))))))} -> All Products done | D7: Anastasia | E7: Cholera | F7: Yemen | G7: Not applicable | K7: 2017-E000187 | M7: No | P7: Yes | R7: disseminated | S7: 44322 | U7: 44364 | Y7: no | AB7: 21 June: not planned | AI7: no | AM7: =VLOOKUP(Table2[[#This Row],[country]],Countrycode!A:B,2,FALSE) -> YEM | AN7: =IF(ISBLANK(Table2[[#This Row],[Need_RRA]]), 2,(IF(Table2[[#This Row],[Need_RRA]]="No", 0, (IF(AND(Table2[[#This Row],[Need_RRA]]="Yes", Table2[[#This Row],[RRA_pub_date]]=""),1, 0))))) -> 0 | AO7: =IF(ISBLANK(Table2[[#This Row],[Need_EIS]]), 2,(IF(Table2[[#This Row],[Need_EIS]]="No", 0, (IF(AND(Table2[[#This Row],[Need_EIS]]="Yes", Table2[[#This Row],[EIS_pub_date]]=""),1, 0))))) -> 0 | AP7: =IF(ISBLANK(Table2[[#This Row],[Need_DON]]), 2,(IF(Table2[[#This Row],[Need_DON]]="No", 0, (IF(AND(Table2[[#This Row],[Need_DON]]="Yes", Table2[[#This Row],[DON_pub_date]]=""),1, 0))))) -> 0 | AQ7: =IF(ISBLANK(Table2[[#This Row],[Pending_question]]), 2,(IF(Table2[[#This Row],[Pending_question]]="Yes", 1, 0))) -> 0
A8: 44328 | B8: Closed | C8: {=IF(SUM(Table2[[#This Row],[PQ_indic]],Table2[[#This Row],[RRA_indic]],Table2[[#This Row],[EIS_indic]],Table2[[#This Row],[DON_indic]])=8, "Missing data", (IF(AND(Table2[[#This Row],[Pending_question]]="Yes", OR( Table2[[#This Row],[Need_RRA]]="No", ISBLANK(Table2[[#This Row],[Need_RRA]])), OR(Table2[[#This Row],[Need_EIS]]="No", ISBLANK(Table2[[#This Row],[Need_EIS]])), OR(Table2[[#This Row],[Need_DON]]="No", ISBLANK(Table2[[#This Row],[Need_DON]]) )),"Question, no products",( IF( AND(Table2[[#This Row],[Pending_question]]="Yes", ISBLANK(Table2[[#This Row],[PQ_closure_date]])), (IF(SUM(Table2[[#This Row],[RRA_indic]],Table2[[#This Row],[EIS_indic]],Table2[[#This Row],[DON_indic]])=0, "Open Question, all products done",(I447IF(OR(Table2[[#This Row],[RRA_indic]]=2, Table2[[#This Row],[EIS_indic]]=2, Table2[[#This Row],[DON_indic]]=2),"Question, Products unknown",IF(AND(Table2[[#This Row],[RRA_indic]]=1, Table2[[#This Row],[EIS_indic]]=1, Table2[[#This Row],[DON_indic]]=1), "Open Question, RRA, EIS, DON", IF(AND(Table2[[#This Row],[RRA_indic]]=1, Table2[[#This Row],[EIS_indic]]=1), "Open Question, RRA, EIS",IF(AND(Table2[[#This Row],[RRA_indic]]=1, Table2[[#This Row],[DON_indic]]=1), "Open Question, RRA, DON", IF(AND(Table2[[#This Row],[EIS_indic]]=1, Table2[[#This Row],[DON_indic]]=1), "Open Question, EIS, DON",IF(Table2[[#This Row],[RRA_indic]]=1, "Open Question, RRA", IF(Table2[[#This Row],[EIS_indic]]=1, "Open Question, EIS", "Open Question, DON")))))))))), (IF(SUM(Table2[[#This Row],[RRA_indic]],Table2[[#This Row],[EIS_indic]],Table2[[#This Row],[DON_indic]])=0, "All Products done",(IF(OR(Table2[[#This Row],[RRA_indic]]=2, Table2[[#This Row],[EIS_indic]]=2, Table2[[#This Row],[DON_indic]]=2),"Unknown", IF(AND(Table2[[#This Row],[RRA_indic]]=1, Table2[[#This Row],[EIS_indic]]=1, Table2[[#This Row],[DON_indic]]=1), "Open RRA, EIS, DON", IF(AND(Table2[[#This Row],[RRA_indic]]=1, Table2[[#This Row],[EIS_indic]]=1), "Open RRA, EIS", IF(AND(Table2[[#This Row],[RRA_indic]]=1, Table2[[#This Row],[DON_indic]]=1), "Open RRA, DON", IF(AND(Table2[[#This Row],[EIS_indic]]=1, Table2[[#This Row],[DON_indic]]=1), "Open EIS, DON", IF(Table2[[#This Row],[RRA_indic]]=1, "Open RRA", IF(Table2[[#This Row],[EIS_indic]]=1, "Open EIS", "Open DON")))))))))))))))} -> All Products done | D8: Anastasia | E8: Cholera | F8: Nigeria | G8: Not applicable | H8: 44328 | I8: 44342 | J8: 44336 | K8: 2021-E000172 | M8: No | P8: Yes | Q8: 1 | R8: disseminated | S8: 44344 | U8: 44357 | V8: High | W8: Moderate | X8: Low | Y8: yes | Z8: New EIS | AB8: 15 June: First draft shared with TT and TT provided comment/ 16 June: draft shared with AFRO and WCO Inputs expected by COB 17 June. Published on 21 June | AC8: 44362 | AE8: 44363 | AG8: 44368 | AH8: 44368 | AI8: no | AM8: =VLOOKUP(Table2[[#This Row],[country]],Countrycode!A:B,2,FALSE) -> NGA | AN8: =IF(ISBLANK(Table2[[#This Row],[Need_RRA]]), 2,(IF(Table2[[#This Row],[Need_RRA]]="No", 0, (IF(AND(Table2[[#This Row],[Need_RRA]]="Yes", Table2[[#This Row],[RRA_pub_date]]=""),1, 0))))) -> 0 | AO8: =IF(ISBLANK(Table2[[#This Row],[Need_EIS]]), 2,(IF(Table2[[#This Row],[Need_EIS]]="No", 0, (IF(AND(Table2[[#This Row],[Need_EIS]]="Yes", Table2[[#This Row],[EIS_pub_date]]=""),1, 0))))) -> 0 | AP8: =IF(ISBLANK(Table2[[#This Row],[Need_DON]]), 2,(IF(Table2[[#This Row],[Need_DON]]="No", 0, (IF(AND(Table2[[#This Row],[Need_DON]]="Yes", Table2[[#This Row],[DON_pub_date]]=""),1, 0))))) -> 0 | AQ8: =IF(ISBLANK(Table2[[#This Row],[Pending_question]]), 2,(IF(Table2[[#This Row],[Pending_question]]="Yes", 1, 0))) -> 0
A9: 44344 | B9: Closed | C9: {=IF(SUM(Table2[[#This Row],[PQ_indic]],Table2[[#This Row],[RRA_indic]],Table2[[#This Row],[EIS_indic]],Table2[[#This Row],[DON_indic]])=8, "Missing data", (IF(AND(Table2[[#This Row],[Pending_question]]="Yes", OR( Table2[[#This Row],[Need_RRA]]="No", ISBLANK(Table2[[#This Row],[Need_RRA]])), OR(Table2[[#This Row],[Need_EIS]]="No", ISBLANK(Table2[[#This Row],[Need_EIS]])), OR(Table2[[#This Row],[Need_DON]]="No", ISBLANK(Table2[[#This Row],[Need_DON]]) )),"Question, no products",( IF( AND(Table2[[#This Row],[Pending_question]]="Yes", ISBLANK(Table2[[#This Row],[PQ_closure_date]])), (IF(SUM(Table2[[#This Row],[RRA_indic]],Table2[[#This Row],[EIS_indic]],Table2[[#This Row],[DON_indic]])=0, "Open Question, all products done",(I447IF(OR(Table2[[#This Row],[RRA_indic]]=2, Table2[[#This Row],[EIS_indic]]=2, Table2[[#This Row],[DON_indic]]=2),"Question, Products unknown",IF(AND(Table2[[#This Row],[RRA_indic]]=1, Table2[[#This Row],[EIS_indic]]=1, Table2[[#This Row],[DON_indic]]=1), "Open Question, RRA, EIS, DON", IF(AND(Table2[[#This Row],[RRA_indic]]=1, Table2[[#This Row],[EIS_indic]]=1), "Open Question, RRA, EIS",IF(AND(Table2[[#This Row],[RRA_indic]]=1, Table2[[#This Row],[DON_indic]]=1), "Open Question, RRA, DON", IF(AND(Table2[[#This Row],[EIS_indic]]=1, Table2[[#This Row],[DON_indic]]=1), "Open Question, EIS, DON",IF(Table2[[#This Row],[RRA_indic]]=1, "Open Question, RRA", IF(Table2[[#This Row],[EIS_indic]]=1, "Open Question, EIS", "Open Question, DON")))))))))), (IF(SUM(Table2[[#This Row],[RRA_indic]],Table2[[#This Row],[EIS_indic]],Table2[[#This Row],[DON_indic]])=0, "All Products done",(IF(OR(Table2[[#This Row],[RRA_indic]]=2, Table2[[#This Row],[EIS_indic]]=2, Table2[[#This Row],[DON_indic]]=2),"Unknown", IF(AND(Table2[[#This Row],[RRA_indic]]=1, Table2[[#This Row],[EIS_indic]]=1, Table2[[#This Row],[DON_indic]]=1), "Open RRA, EIS, DON", IF(AND(Table2[[#This Row],[RRA_indic]]=1, Table2[[#This Row],[EIS_indic]]=1), "Open RRA, EIS", IF(AND(Table2[[#This Row],[RRA_indic]]=1, Table2[[#This Row],[DON_indic]]=1), "Open RRA, DON", IF(AND(Table2[[#This Row],[EIS_indic]]=1, Table2[[#This Row],[DON_indic]]=1), "Open EIS, DON", IF(Table2[[#This Row],[RRA_indic]]=1, "Open RRA", IF(Table2[[#This Row],[EIS_indic]]=1, "Open EIS", "Open DON")))))))))))))))} -> All Products done | D9: Lidia/Anastasia | E9: Plague | F9: Democratic Republic of the Congo | G9: Not applicable | K9: 2019-E000123 | M9: No | P9: Yes | R9: 18 June 2021: distributed | S9: 44344 | U9: 44365 | Y9: yes | AB9: 15 June: draft shared with AFRO and HQ colleagues/18 June: feedback from AFRO received . Awaiting WCO inputs /20 June: Reminder sent / 23 June: IHR NFP feedback received / 27 June: EIS posted | AH9: 44374 | AI9: no | AM9: =VLOOKUP(Table2[[#This Row],[country]],Countrycode!A:B,2,FALSE) -> COD | AN9: =IF(ISBLANK(Table2[[#This Row],[Need_RRA]]), 2,(IF(Table2[[#This Row],[Need_RRA]]="No", 0, (IF(AND(Table2[[#This Row],[Need_RRA]]="Yes", Table2[[#This Row],[RRA_pub_date]]=""),1, 0))))) -> 0 | AO9: =IF(ISBLANK(Table2[[#This Row],[Need_EIS]]), 2,(IF(Table2[[#This Row],[Need_EIS]]="No", 0, (IF(AND(Table2[[#This Row],[Need_EIS]]="Yes", Table2[[#This Row],[EIS_pub_date]]=""),1, 0))))) -> 0 | AP9: =IF(ISBLANK(Table2[[#This Row],[Need_DON]]), 2,(IF(Table2[[#This Row],[Need_DON]]="No", 0, (IF(AND(Table2[[#This Row],[Need_DON]]="Yes", Table2[[#This Row],[DON_pub_date]]=""),1, 0))))) -> 0 | AQ9: =IF(ISBLANK(Table2[[#This Row],[Pending_question]]), 2,(IF(Table2[[#This Row],[Pending_question]]="Yes", 1, 0))) -> 0
A10: 44357 | B10: Closed | C10: {=IF(SUM(Table2[[#This Row],[PQ_indic]],Table2[[#This Row],[RRA_indic]],Table2[[#This Row],[EIS_indic]],Table2[[#This Row],[DON_indic]])=8, "Missing data", (IF(AND(Table2[[#This Row],[Pending_question]]="Yes", OR( Table2[[#This Row],[Need_RRA]]="No", ISBLANK(Table2[[#This Row],[Need_RRA]])), OR(Table2[[#This Row],[Need_EIS]]="No", ISBLANK(Table2[[#This Row],[Need_EIS]])), OR(Table2[[#This Row],[Need_DON]]="No", ISBLANK(Table2[[#This Row],[Need_DON]]) )),"Question, no products",( IF( AND(Table2[[#This Row],[Pending_question]]="Yes", ISBLANK(Table2[[#This Row],[PQ_closure_date]])), (IF(SUM(Table2[[#This Row],[RRA_indic]],Table2[[#This Row],[EIS_indic]],Table2[[#This Row],[DON_indic]])=0, "Open Question, all products done",(I447IF(OR(Table2[[#This Row],[RRA_indic]]=2, Table2[[#This Row],[EIS_indic]]=2, Table2[[#This Row],[DON_indic]]=2),"Question, Products unknown",IF(AND(Table2[[#This Row],[RRA_indic]]=1, Table2[[#This Row],[EIS_indic]]=1, Table2[[#This Row],[DON_indic]]=1), "Open Question, RRA, EIS, DON", IF(AND(Table2[[#This Row],[RRA_indic]]=1, Table2[[#This Row],[EIS_indic]]=1), "Open Question, RRA, EIS",IF(AND(Table2[[#This Row],[RRA_indic]]=1, Table2[[#This Row],[DON_indic]]=1), "Open Question, RRA, DON", IF(AND(Table2[[#This Row],[EIS_indic]]=1, Table2[[#This Row],[DON_indic]]=1), "Open Question, EIS, DON",IF(Table2[[#This Row],[RRA_indic]]=1, "Open Question, RRA", IF(Table2[[#This Row],[EIS_indic]]=1, "Open Question, EIS", "Open Question, DON")))))))))), (IF(SUM(Table2[[#This Row],[RRA_indic]],Table2[[#This Row],[EIS_indic]],Table2[[#This Row],[DON_indic]])=0, "All Products done",(IF(OR(Table2[[#This Row],[RRA_indic]]=2, Table2[[#This Row],[EIS_indic]]=2, Table2[[#This Row],[DON_indic]]=2),"Unknown", IF(AND(Table2[[#This Row],[RRA_indic]]=1, Table2[[#This Row],[EIS_indic]]=1, Table2[[#This Row],[DON_indic]]=1), "Open RRA, EIS, DON", IF(AND(Table2[[#This Row],[RRA_indic]]=1, Table2[[#This Row],[EIS_indic]]=1), "Open RRA, EIS", IF(AND(Table2[[#This Row],[RRA_indic]]=1, Table2[[#This Row],[DON_indic]]=1), "Open RRA, DON", IF(AND(Table2[[#This Row],[EIS_indic]]=1, Table2[[#This Row],[DON_indic]]=1), "Open EIS, DON", IF(Table2[[#This Row],[RRA_indic]]=1, "Open RRA", IF(Table2[[#This Row],[EIS_indic]]=1, "Open EIS", "Open DON")))))))))))))))} -> All Products done | D10: Lidia | E10: Zika | F10: India | G10: Not applicable | H10: 09 June, 11 June | J10: 44357 | K10: 2021-E000253 | M10: No | P10: Yes | R10: 12 July 2021: Not Planned / 15 July: we need one RRA / 16 July: 3LTC: no RRA for the moment as the magnitude of the event is not clear, "we need more data and information" Email requesting 3LTC and further discussion sent on 26 July./ 28 July: SEARO agreed to have a RRA, CO will draft it. 30 July - 1st Draft RRA received by SEARO. Shared with the TTHQ. Deadline 11am on Tuesday, 2 August. RRA with major adjustments shared back with SEARO on 5 August and requested for 3 LTC. / 5 August received inputs by TT tha have been incorportaed to the final draft. On 9 August a follow up email sent regarding the status of the RRA and EIS with proposition for a 3LTC. Replied recieved on 10 August - the comments of the RRA will be addressed and decline of the 3 LTC at this stage. RRA draft received on 11 August by SEARO with some of the comments addressed in the document. 3LTC held on 17 August. RRA dissseminated on 17 August. | S10: 44407 | U10: 44425 | Y10: yes | AB10: 15 July: we need an EIS / 16 July: CO will draft an EIS, check the deadline / 20 July: reminder sent to SEARO and SEARO shared the draft with NCDC / 22 July: EIS still pending draft from WCO / 26 July: still waiting inputs from NCDC.SEARO replied on 26 July that they are expecting the draft to be likely approved by the evening of 26 July 2021. On 28 July, SEARO provided epi update and stated theat the EIS is with the MoH for clearance. We have requested the EIS draft, as it hasn't been shared with HQ +TT, for further inputs, prior to the accuracy check. EIS received on 29 July and shared with the TT for further inputs by 3PM on 29 July. Draft EIS with HQ inputs sent back to SEARO by COB on 29 July. Final draft EIS sent for NFP concurrence on 30 July.On 9 August a follow up email sent regarding the status of the RRA and EIS with proposition for a 3LTC, as the EIS is already outdated. Replied received from SEARO on 10 August, WCO and RO, just had a call this morning. WCO colleagues have kindly agreed to address the pending comments and share a new draft as soon as possible. With this in mind, and given the many other competing priorities, we would like to politely decline the invitation for a 3LTC today. Specifically on the contents, WCO colleagues will add the latest information on the subtype from vectors and human samples. With regard to the status of the EIS, WCO is in regular contact with national counterparts. Following the 3LTC on 17 August, it was agreed that PHI will update the EIS draft , including the 2nd state and will share back with WCO for NFP concurrence. 27 August: The old EIS received with withe the NFP concurrence. 3 September: a new version of the EIS has been drafted by PHI and shared for comments at HQ level . 6 September: EIS draft shared with SEARO. Awaiting SEARO to address the pending comments, prior to sharing with the NFP.10 September: Final EIS sent back to SEARO for NFP concurrence. 15 September: Reminder sent to SEARO. / 16 September: reminder to SEARO by Emilie / 20 Sep: SEARO replied that NFP/NCDC does not concur with the classification of the event as presenting a serious pubic health impact. Their reply: “Further to our discussion and as directed by the Director, NCDC, the justification for RA for Zika is as given below: Serious Public Health Impact – No Majority of people infected with Zika virus do not develop symptoms and even those who are symptomatic develop only mild symptoms lasting for 2-7 days. India is endemic for dengue, therefore, the health system is well geared to manage and respond to any unprecedented surge in Zika cases, which has almost similar presentation as dengue. There is an increased risk of neurologic complications associated with Zika virus infection in adults and children, including Guillain-Barré syndrome, neuropathy and myelitis. Although the current evidence available from the previous Zika outbreaks in the country, has not shown any conclusive evidence on Zika induced microcephaly. Therefore, the risk has been classified as low for serious public health impact. This is for info and na pls.” 21 Sptember: TC proposed for 22 September to WCO for further agreement on the EIS.22 September: 3LTC held.Outputs - Ritu will send to outbreak the EIS with comments from the NFP an update of the situation. Diana and Lidia will compile the information and update the EIS, they will circulate the EIS with SEARO and CO for final clearance (we will not go through IHR NFP) Agreed to have: *no" to IHR criteria #1 but nuanced text, an updated description of the situation, a DON will follow. Reassess the situation in a couple of months. Emilie has sent the EIS guidance to Ritu. Need trainings on RA and EIS: Lidia and Emilie to see what is feasible. On 24 September meeting held. Training materials are being prepared by LIdia in the week of 27 september. 27 September: TT shared with the RO and WCO group the preprint article for the Zika event. 29 September escaleted to the SM. 30 September: RED contacted / 4 October: EIS posting is cleared but not posted yet because of the EIS technical issues / 5 October: EIS posted | AH10: 44474 | AI10: yes | AK10: 44483 | AL10: 12 July: email sent to SEARO and TT to informaly assess the situation / 15 July: email received from TT with additional information, the situation is concerning, we need RRA and EIS. After the TC on 16 July, there is no need for RRA at the moment. | AM10: =VLOOKUP(Table2[[#This Row],[country]],Countrycode!A:B,2,FALSE) -> IND | AN10: =IF(ISBLANK(Table2[[#This Row],[Need_RRA]]), 2,(IF(Table2[[#This Row],[Need_RRA]]="No", 0, (IF(AND(Table2[[#This Row],[Need_RRA]]="Yes", Table2[[#This Row],[RRA_pub_date]]=""),1, 0))))) -> 0 | AO10: =IF(ISBLANK(Table2[[#This Row],[Need_EIS]]), 2,(IF(Table2[[#This Row],[Need_EIS]]="No", 0, (IF(AND(Table2[[#This Row],[Need_EIS]]="Yes", Table2[[#This Row],[EIS_pub_date]]=""),1, 0))))) -> 0 | AP10: =IF(ISBLANK(Table2[[#This Row],[Need_DON]]), 2,(IF(Table2[[#This Row],[Need_DON]]="No", 0, (IF(AND(Table2[[#This Row],[Need_DON]]="Yes", Table2[[#This Row],[DON_pub_date]]=""),1, 0))))) -> 0 | AQ10: =IF(ISBLANK(Table2[[#This Row],[Pending_question]]), 2,(IF(Table2[[#This Row],[Pending_question]]="Yes", 1, 0))) -> 0 | AR10: 09 June, 11 June
A11: 44358 | B11: Closed | C11: {=IF(SUM(Table2[[#This Row],[PQ_indic]],Table2[[#This Row],[RRA_indic]],Table2[[#This Row],[EIS_indic]],Table2[[#This Row],[DON_indic]])=8, "Missing data", (IF(AND(Table2[[#This Row],[Pending_question]]="Yes", OR( Table2[[#This Row],[Need_RRA]]="No", ISBLANK(Table2[[#This Row],[Need_RRA]])), OR(Table2[[#This Row],[Need_EIS]]="No", ISBLANK(Table2[[#This Row],[Need_EIS]])), OR(Table2[[#This Row],[Need_DON]]="No", ISBLANK(Table2[[#This Row],[Need_DON]]) )),"Question, no products",( IF( AND(Table2[[#This Row],[Pending_question]]="Yes", ISBLANK(Table2[[#This Row],[PQ_closure_date]])), (IF(SUM(Table2[[#This Row],[RRA_indic]],Table2[[#This Row],[EIS_indic]],Table2[[#This Row],[DON_indic]])=0, "Open Question, all products done",(I447IF(OR(Table2[[#This Row],[RRA_indic]]=2, Table2[[#This Row],[EIS_indic]]=2, Table2[[#This Row],[DON_indic]]=2),"Question, Products unknown",IF(AND(Table2[[#This Row],[RRA_indic]]=1, Table2[[#This Row],[EIS_indic]]=1, Table2[[#This Row],[DON_indic]]=1), "Open Question, RRA, EIS, DON", IF(AND(Table2[[#This Row],[RRA_indic]]=1, Table2[[#This Row],[EIS_indic]]=1), "Open Question, RRA, EIS",IF(AND(Table2[[#This Row],[RRA_indic]]=1, Table2[[#This Row],[DON_indic]]=1), "Open Question, RRA, DON", IF(AND(Table2[[#This Row],[EIS_indic]]=1, Table2[[#This Row],[DON_indic]]=1), "Open Question, EIS, DON",IF(Table2[[#This Row],[RRA_indic]]=1, "Open Question, RRA", IF(Table2[[#This Row],[EIS_indic]]=1, "Open Question, EIS", "Open Question, DON")))))))))), (IF(SUM(Table2[[#This Row],[RRA_indic]],Table2[[#This Row],[EIS_indic]],Table2[[#This Row],[DON_indic]])=0, "All Products done",(IF(OR(Table2[[#This Row],[RRA_indic]]=2, Table2[[#This Row],[EIS_indic]]=2, Table2[[#This Row],[DON_indic]]=2),"Unknown", IF(AND(Table2[[#This Row],[RRA_indic]]=1, Table2[[#This Row],[EIS_indic]]=1, Table2[[#This Row],[DON_indic]]=1), "Open RRA, EIS, DON", IF(AND(Table2[[#This Row],[RRA_indic]]=1, Table2[[#This Row],[EIS_indic]]=1), "Open RRA, EIS", IF(AND(Table2[[#This Row],[RRA_indic]]=1, Table2[[#This Row],[DON_indic]]=1), "Open RRA, DON", IF(AND(Table2[[#This Row],[EIS_indic]]=1, Table2[[#This Row],[DON_indic]]=1), "Open EIS, DON", IF(Table2[[#This Row],[RRA_indic]]=1, "Open RRA", IF(Table2[[#This Row],[EIS_indic]]=1, "Open EIS", "Open DON")))))))))))))))} -> All Products done | D11: Etsub | E11: Avian influenza A (H1N2) | F11: China, Province of Taiwan | G11: Not applicable | H11: 44358 | J11: 44356 | M11: No | P11: No | Q11: Not applicable | R11: No RRA | Y11: yes | AB11: Comments from IHR secretariat received from Fernando on 14 June. Further guidance on how to proceed pending from LEG. Reminder sent to LEG on 17 June, Input received from LEG on 18 June. Reminder sent to LEG for the guidance on the way how to get a consultation for the document. A follow up meeting with LEG and IHR conducted on 23 June. Pending LEG’s advice on how to proceed with this 23 June / 28 June: LEG replied, they are exploring how to proceed with IHR NFP consultation / 29 June: LEG replied: they will consult with the with relevant officials on 30 June / published on 2 July | AH11: 44379 | AI11: no | AL11: we don’t know how to proceed with NFP consultation, LEG does not reply. LEG is going to reply by COB 1 July 2021. LEG gave a green light for posting. It will be posted on 1 July. | AM11: =VLOOKUP(Table2[[#This Row],[country]],Countrycode!A:B,2,FALSE) -> TWN | AN11: =IF(ISBLANK(Table2[[#This Row],[Need_RRA]]), 2,(IF(Table2[[#This Row],[Need_RRA]]="No", 0, (IF(AND(Table2[[#This Row],[Need_RRA]]="Yes", Table2[[#This Row],[RRA_pub_date]]=""),1, 0))))) -> 0 | AO11: =IF(ISBLANK(Table2[[#This Row],[Need_EIS]]), 2,(IF(Table2[[#This Row],[Need_EIS]]="No", 0, (IF(AND(Table2[[#This Row],[Need_EIS]]="Yes", Table2[[#This Row],[EIS_pub_date]]=""),1, 0))))) -> 0 | AP11: =IF(ISBLANK(Table2[[#This Row],[Need_DON]]), 2,(IF(Table2[[#This Row],[Need_DON]]="No", 0, (IF(AND(Table2[[#This Row],[Need_DON]]="Yes", Table2[[#This Row],[DON_pub_date]]=""),1, 0))))) -> 0 | AQ11: =IF(ISBLANK(Table2[[#This Row],[Pending_question]]), 2,(IF(Table2[[#This Row],[Pending_question]]="Yes", 1, 0))) -> 0 | AR11: 44358
A12: 44361 | B12: Closed | C12: {=IF(SUM(Table2[[#This Row],[PQ_indic]],Table2[[#This Row],[RRA_indic]],Table2[[#This Row],[EIS_indic]],Table2[[#This Row],[DON_indic]])=8, "Missing data", (IF(AND(Table2[[#This Row],[Pending_question]]="Yes", OR( Table2[[#This Row],[Need_RRA]]="No", ISBLANK(Table2[[#This Row],[Need_RRA]])), OR(Table2[[#This Row],[Need_EIS]]="No", ISBLANK(Table2[[#This Row],[Need_EIS]])), OR(Table2[[#This Row],[Need_DON]]="No", ISBLANK(Table2[[#This Row],[Need_DON]]) )),"Question, no products",( IF( AND(Table2[[#This Row],[Pending_question]]="Yes", ISBLANK(Table2[[#This Row],[PQ_closure_date]])), (IF(SUM(Table2[[#This Row],[RRA_indic]],Table2[[#This Row],[EIS_indic]],Table2[[#This Row],[DON_indic]])=0, "Open Question, all products done",(I447IF(OR(Table2[[#This Row],[RRA_indic]]=2, Table2[[#This Row],[EIS_indic]]=2, Table2[[#This Row],[DON_indic]]=2),"Question, Products unknown",IF(AND(Table2[[#This Row],[RRA_indic]]=1, Table2[[#This Row],[EIS_indic]]=1, Table2[[#This Row],[DON_indic]]=1), "Open Question, RRA, EIS, DON", IF(AND(Table2[[#This Row],[RRA_indic]]=1, Table2[[#This Row],[EIS_indic]]=1), "Open Question, RRA, EIS",IF(AND(Table2[[#This Row],[RRA_indic]]=1, Table2[[#This Row],[DON_indic]]=1), "Open Question, RRA, DON", IF(AND(Table2[[#This Row],[EIS_indic]]=1, Table2[[#This Row],[DON_indic]]=1), "Open Question, EIS, DON",IF(Table2[[#This Row],[RRA_indic]]=1, "Open Question, RRA", IF(Table2[[#This Row],[EIS_indic]]=1, "Open Question, EIS", "Open Question, DON")))))))))), (IF(SUM(Table2[[#This Row],[RRA_indic]],Table2[[#This Row],[EIS_indic]],Table2[[#This Row],[DON_indic]])=0, "All Products done",(IF(OR(Table2[[#This Row],[RRA_indic]]=2, Table2[[#This Row],[EIS_indic]]=2, Table2[[#This Row],[DON_indic]]=2),"Unknown", IF(AND(Table2[[#This Row],[RRA_indic]]=1, Table2[[#This Row],[EIS_indic]]=1, Table2[[#This Row],[DON_indic]]=1), "Open RRA, EIS, DON", IF(AND(Table2[[#This Row],[RRA_indic]]=1, Table2[[#This Row],[EIS_indic]]=1), "Open RRA, EIS", IF(AND(Table2[[#This Row],[RRA_indic]]=1, Table2[[#This Row],[DON_indic]]=1), "Open RRA, DON", IF(AND(Table2[[#This Row],[EIS_indic]]=1, Table2[[#This Row],[DON_indic]]=1), "Open EIS, DON", IF(Table2[[#This Row],[RRA_indic]]=1, "Open RRA", IF(Table2[[#This Row],[EIS_indic]]=1, "Open EIS", "Open DON")))))))))))))))} -> All Products done | D12: Lida/Elvis | E12: Yellow Fever | F12: Cameroon | G12: Not applicable | K12: 2021-E000046 | M12: No | P12: Yes | R12: Proposal for an RRA sent to AFRO on 15 June. AFRO agreed to the proposal on 16 June. Awaiting approval from WCO. Drafted by CO, shared with AFRO, should be shared with HQ on 29 June/29 July: RRA shares with HQ/30 July: HQ adds inputs and disseminates to TT/01 July: TT adds inputs/02 July: Version from HQ+TT sent back to AFRO. Feedback expected by COB on 05 July. / 7 July: sent back to AFRO, still waiting for CO update (reminder sent on 6 July)/ 9 July: waiting for AFRO's feedback / 12 July: reply from CO / 13 July: reply recieved from WCO & AFRO, reshared with Emilie for review/14 July: to share with TT for review/16 July: RRA sent back to AFRO and WCO to address pending comments / 19 July: Feedback expected by COB Monday 19 July / 20 July: WCO and AFRO shared revised version. Risk level at national level assessed as HIGH /21 July: To share consolidated version with Esther for clearance by COB. / 23 July: disseminated | S12: 44361 | U12: 44400 | Y12: yes | AB12: 5 July: no EIS planned / 19 July: EIS planned after RRA is completed/27 July: initiated discussions on the EIS. AFRO suggested to contact WCO to get their opinion before proceding with the draft EIS in French and English. Initial draft (french and english version) shared by AFRO on 3 August. Inputs reuested from HQ TT by 1pm on 4 August.Shared back with AFRO on 5 August. Final consolidated draft EIS recieved from AFRO on 9 August. Following final clearance sent back to AFRO for NFP consultation on xx August/12 August: WCO&AFRO addressed comments/13 August: Final cleared version sent to AFRO for NFP consultation./18 August: Remider regarding the NFP concurence sent to AFRo. Reminder sent on 20 and 24 August. Folllow up sent on 26 August. /27 August: EIS posted. Reminder sent to AFRO on 30 August for the french version of the EIS. Reply received on 31 Agust that they will share soon. | AH12: 44435 | AI12: no | AL12: MOH was busy with the pilgrim season in the last two weeks | AM12: =VLOOKUP(Table2[[#This Row],[country]],Countrycode!A:B,2,FALSE) -> CMR | AN12: =IF(ISBLANK(Table2[[#This Row],[Need_RRA]]), 2,(IF(Table2[[#This Row],[Need_RRA]]="No", 0, (IF(AND(Table2[[#This Row],[Need_RRA]]="Yes", Table2[[#This Row],[RRA_pub_date]]=""),1, 0))))) -> 0 | AO12: =IF(ISBLANK(Table2[[#This Row],[Need_EIS]]), 2,(IF(Table2[[#This Row],[Need_EIS]]="No", 0, (IF(AND(Table2[[#This Row],[Need_EIS]]="Yes", Table2[[#This Row],[EIS_pub_date]]=""),1, 0))))) -> 0 | AP12: =IF(ISBLANK(Table2[[#This Row],[Need_DON]]), 2,(IF(Table2[[#This Row],[Need_DON]]="No", 0, (IF(AND(Table2[[#This Row],[Need_DON]]="Yes", Table2[[#This Row],[DON_pub_date]]=""),1, 0))))) -> 0 | AQ12: =IF(ISBLANK(Table2[[#This Row],[Pending_question]]), 2,(IF(Table2[[#This Row],[Pending_question]]="Yes", 1, 0))) -> 0
A13: 44366 | B13: Closed | C13: {=IF(SUM(Table2[[#This Row],[PQ_indic]],Table2[[#This Row],[RRA_indic]],Table2[[#This Row],[EIS_indic]],Table2[[#This Row],[DON_indic]])=8, "Missing data", (IF(AND(Table2[[#This Row],[Pending_question]]="Yes", OR( Table2[[#This Row],[Need_RRA]]="No", ISBLANK(Table2[[#This Row],[Need_RRA]])), OR(Table2[[#This Row],[Need_EIS]]="No", ISBLANK(Table2[[#This Row],[Need_EIS]])), OR(Table2[[#This Row],[Need_DON]]="No", ISBLANK(Table2[[#This Row],[Need_DON]]) )),"Question, no products",( IF( AND(Table2[[#This Row],[Pending_question]]="Yes", ISBLANK(Table2[[#This Row],[PQ_closure_date]])), (IF(SUM(Table2[[#This Row],[RRA_indic]],Table2[[#This Row],[EIS_indic]],Table2[[#This Row],[DON_indic]])=0, "Open Question, all products done",(I447IF(OR(Table2[[#This Row],[RRA_indic]]=2, Table2[[#This Row],[EIS_indic]]=2, Table2[[#This Row],[DON_indic]]=2),"Question, Products unknown",IF(AND(Table2[[#This Row],[RRA_indic]]=1, Table2[[#This Row],[EIS_indic]]=1, Table2[[#This Row],[DON_indic]]=1), "Open Question, RRA, EIS, DON", IF(AND(Table2[[#This Row],[RRA_indic]]=1, Table2[[#This Row],[EIS_indic]]=1), "Open Question, RRA, EIS",IF(AND(Table2[[#This Row],[RRA_indic]]=1, Table2[[#This Row],[DON_indic]]=1), "Open Question, RRA, DON", IF(AND(Table2[[#This Row],[EIS_indic]]=1, Table2[[#This Row],[DON_indic]]=1), "Open Question, EIS, DON",IF(Table2[[#This Row],[RRA_indic]]=1, "Open Question, RRA", IF(Table2[[#This Row],[EIS_indic]]=1, "Open Question, EIS", "Open Question, DON")))))))))), (IF(SUM(Table2[[#This Row],[RRA_indic]],Table2[[#This Row],[EIS_indic]],Table2[[#This Row],[DON_indic]])=0, "All Products done",(IF(OR(Table2[[#This Row],[RRA_indic]]=2, Table2[[#This Row],[EIS_indic]]=2, Table2[[#This Row],[DON_indic]]=2),"Unknown", IF(AND(Table2[[#This Row],[RRA_indic]]=1, Table2[[#This Row],[EIS_indic]]=1, Table2[[#This Row],[DON_indic]]=1), "Open RRA, EIS, DON", IF(AND(Table2[[#This Row],[RRA_indic]]=1, Table2[[#This Row],[EIS_indic]]=1), "Open RRA, EIS", IF(AND(Table2[[#This Row],[RRA_indic]]=1, Table2[[#This Row],[DON_indic]]=1), "Open RRA, DON", IF(AND(Table2[[#This Row],[EIS_indic]]=1, Table2[[#This Row],[DON_indic]]=1), "Open EIS, DON", IF(Table2[[#This Row],[RRA_indic]]=1, "Open RRA", IF(Table2[[#This Row],[EIS_indic]]=1, "Open EIS", "Open DON")))))))))))))))} -> All Products done | D13: Anastasia | E13: Ebola virus disease | F13: Guinea | G13: Not applicable | M13: No | P13: No | Q13: Not applicable | Y13: yes | AB13: 18 june: sent back to Ros for NFP consultation/19 June: published | AH13: 44366 | AI13: yes | AK13: 44366 | AM13: =VLOOKUP(Table2[[#This Row],[country]],Countrycode!A:B,2,FALSE) -> GIN | AN13: =IF(ISBLANK(Table2[[#This Row],[Need_RRA]]), 2,(IF(Table2[[#This Row],[Need_RRA]]="No", 0, (IF(AND(Table2[[#This Row],[Need_RRA]]="Yes", Table2[[#This Row],[RRA_pub_date]]=""),1, 0))))) -> 0 | AO13: =IF(ISBLANK(Table2[[#This Row],[Need_EIS]]), 2,(IF(Table2[[#This Row],[Need_EIS]]="No", 0, (IF(AND(Table2[[#This Row],[Need_EIS]]="Yes", Table2[[#This Row],[EIS_pub_date]]=""),1, 0))))) -> 0 | AP13: =IF(ISBLANK(Table2[[#This Row],[Need_DON]]), 2,(IF(Table2[[#This Row],[Need_DON]]="No", 0, (IF(AND(Table2[[#This Row],[Need_DON]]="Yes", Table2[[#This Row],[DON_pub_date]]=""),1, 0))))) -> 0 | AQ13: =IF(ISBLANK(Table2[[#This Row],[Pending_question]]), 2,(IF(Table2[[#This Row],[Pending_question]]="Yes", 1, 0))) -> 0
A14: 44367 | B14: Closed | C14: {=IF(SUM(Table2[[#This Row],[PQ_indic]],Table2[[#This Row],[RRA_indic]],Table2[[#This Row],[EIS_indic]],Table2[[#This Row],[DON_indic]])=8, "Missing data", (IF(AND(Table2[[#This Row],[Pending_question]]="Yes", OR( Table2[[#This Row],[Need_RRA]]="No", ISBLANK(Table2[[#This Row],[Need_RRA]])), OR(Table2[[#This Row],[Need_EIS]]="No", ISBLANK(Table2[[#This Row],[Need_EIS]])), OR(Table2[[#This Row],[Need_DON]]="No", ISBLANK(Table2[[#This Row],[Need_DON]]) )),"Question, no products",( IF( AND(Table2[[#This Row],[Pending_question]]="Yes", ISBLANK(Table2[[#This Row],[PQ_closure_date]])), (IF(SUM(Table2[[#This Row],[RRA_indic]],Table2[[#This Row],[EIS_indic]],Table2[[#This Row],[DON_indic]])=0, "Open Question, all products done",(I447IF(OR(Table2[[#This Row],[RRA_indic]]=2, Table2[[#This Row],[EIS_indic]]=2, Table2[[#This Row],[DON_indic]]=2),"Question, Products unknown",IF(AND(Table2[[#This Row],[RRA_indic]]=1, Table2[[#This Row],[EIS_indic]]=1, Table2[[#This Row],[DON_indic]]=1), "Open Question, RRA, EIS, DON", IF(AND(Table2[[#This Row],[RRA_indic]]=1, Table2[[#This Row],[EIS_indic]]=1), "Open Question, RRA, EIS",IF(AND(Table2[[#This Row],[RRA_indic]]=1, Table2[[#This Row],[DON_indic]]=1), "Open Question, RRA, DON", IF(AND(Table2[[#This Row],[EIS_indic]]=1, Table2[[#This Row],[DON_indic]]=1), "Open Question, EIS, DON",IF(Table2[[#This Row],[RRA_indic]]=1, "Open Question, RRA", IF(Table2[[#This Row],[EIS_indic]]=1, "Open Question, EIS", "Open Question, DON")))))))))), (IF(SUM(Table2[[#This Row],[RRA_indic]],Table2[[#This Row],[EIS_indic]],Table2[[#This Row],[DON_indic]])=0, "All Products done",(IF(OR(Table2[[#This Row],[RRA_indic]]=2, Table2[[#This Row],[EIS_indic]]=2, Table2[[#This Row],[DON_indic]]=2),"Unknown", IF(AND(Table2[[#This Row],[RRA_indic]]=1, Table2[[#This Row],[EIS_indic]]=1, Table2[[#This Row],[DON_indic]]=1), "Open RRA, EIS, DON", IF(AND(Table2[[#This Row],[RRA_indic]]=1, Table2[[#This Row],[EIS_indic]]=1), "Open RRA, EIS", IF(AND(Table2[[#This Row],[RRA_indic]]=1, Table2[[#This Row],[DON_indic]]=1), "Open RRA, DON", IF(AND(Table2[[#This Row],[EIS_indic]]=1, Table2[[#This Row],[DON_indic]]=1), "Open EIS, DON", IF(Table2[[#This Row],[RRA_indic]]=1, "Open RRA", IF(Table2[[#This Row],[EIS_indic]]=1, "Open EIS", "Open DON")))))))))))))))} -> All Products done | D14: Lidia/Anastasia/Elvis /Etsub | E14: Dengue | F14: Kenya | G14: Not applicable | K14: 2021-E000167 | M14: No | P14: Yes | R14: 21 June: Will start the process / 23 June: RRA shared by CO to AFRO and HQ / 24 june, AFRO provided inputs and shared with HQ. HQ then shared with TT. TT provided comments same day/25 June, HQ shared RRA with AFRO/28 June: comments received from WCO, AFRO feedback is pending / 29 June: AFRO provided inputs and changed level of risk of event spreading at national and regional level from moderate to high/2 July: Amended version shared with AFRO and WCO/3 July: WCO accepted changes / 5 July: waiting for AFRO greenlight / 7 July: more comments from Esther, needs to go back to AFRO and CO / 8 July: Finalized and distributed | S14: 44367 | U14: 44385 | Y14: yes | AB14: 21 June: need one/ EIS to be drafted immediately RRA is completed/ 9 July: HQ is drafting the EIS/ 14 July: EIS drafted by HQ and shared with TT, inputs from TT are received/ 15 July: shared with AFRO and CO for comments (deadline for tomorrow)/ 16 July: CO shared comments, reminder sent to AFRO/16 July: Revised version sent back AFRO after receving input from WCO. AFRO is expected to share with IHR NFP for consultation if there is no outstanding comment/ 20 July: reminder sent to AFRO /21 July: AFRO responded to indicate they will share with NFP for consultation /23 July: EIS has been shared with IHR NFP and is pending feedback from the NFP/ 23 July: Final EIS for posting shared by AFRO./26 July: EIS published. | AH14: 44403 | AI14: no | AL14: 20 June: sitrep received, dengue confirmed by RT PCR/latest line as of 29 June recieved on 02 July 2021 | AM14: =VLOOKUP(Table2[[#This Row],[country]],Countrycode!A:B,2,FALSE) -> KEN | AN14: =IF(ISBLANK(Table2[[#This Row],[Need_RRA]]), 2,(IF(Table2[[#This Row],[Need_RRA]]="No", 0, (IF(AND(Table2[[#This Row],[Need_RRA]]="Yes", Table2[[#This Row],[RRA_pub_date]]=""),1, 0))))) -> 0 | AO14: =IF(ISBLANK(Table2[[#This Row],[Need_EIS]]), 2,(IF(Table2[[#This Row],[Need_EIS]]="No", 0, (IF(AND(Table2[[#This Row],[Need_EIS]]="Yes", Table2[[#This Row],[EIS_pub_date]]=""),1, 0))))) -> 0 | AP14: =IF(ISBLANK(Table2[[#This Row],[Need_DON]]), 2,(IF(Table2[[#This Row],[Need_DON]]="No", 0, (IF(AND(Table2[[#This Row],[Need_DON]]="Yes", Table2[[#This Row],[DON_pub_date]]=""),1, 0))))) -> 0 | AQ14: =IF(ISBLANK(Table2[[#This Row],[Pending_question]]), 2,(IF(Table2[[#This Row],[Pending_question]]="Yes", 1, 0))) -> 0
